<?xml version="1.0" ?>
<robot name="antsy" xmlns:xacro="http://www.ros.org/wiki/xacro">

<xacro:include filename="$(find antsy_description)/urdf/materials.xacro" />
<xacro:include filename="$(find antsy_description)/urdf/antsy.trans" />
<xacro:include filename="$(find antsy_description)/urdf/antsy.gazebo" />
<link name="base_link">
  <inertial>
    <origin xyz="0.00014120578374947324 0.000907462590201314 -0.0004863329579636028" rpy="0 0 0"/>
    <mass value="6.980366975019921"/>
    <inertia ixx="0.035507" iyy="0.050259" izz="0.082758" ixy="8e-06" iyz="4e-06" ixz="-1.7e-05"/>
  </inertial>
  <visual>
    <origin xyz="0 0 0" rpy="0 0 0"/>
    <geometry>
      <mesh filename="file://$(find antsy_description)/meshes/base_link.stl" scale="0.001 0.001 0.001"/>
    </geometry>
    <material name="silver"/>
  </visual>
  <collision>
    <origin xyz="0 0 0" rpy="0 0 0"/>
    <geometry>
      <mesh filename="file://$(find antsy_description)/meshes/base_link.stl" scale="0.001 0.001 0.001"/>
    </geometry>
  </collision>
</link>

<link name="coxa_ml_1">
  <inertial>
    <origin xyz="0.001016190721176123 0.0365910232917165 -0.027523803018169958" rpy="0 0 0"/>
    <mass value="0.06644962989519385"/>
    <inertia ixx="3.4e-05" iyy="3.2e-05" izz="2.4e-05" ixy="-0.0" iyz="0.0" ixz="-0.0"/>
  </inertial>
  <visual>
    <origin xyz="-7.1e-05 -0.120123 -0.027918" rpy="0 0 0"/>
    <geometry>
      <mesh filename="file://$(find antsy_description)/meshes/coxa_ml_1.stl" scale="0.001 0.001 0.001"/>
    </geometry>
    <material name="silver"/>
  </visual>
  <collision>
    <origin xyz="-7.1e-05 -0.120123 -0.027918" rpy="0 0 0"/>
    <geometry>
      <mesh filename="file://$(find antsy_description)/meshes/coxa_ml_1.stl" scale="0.001 0.001 0.001"/>
    </geometry>
  </collision>
</link>

<link name="tibia_ml_1">
  <inertial>
    <origin xyz="0.027400277385198818 0.05047473383178089 9.252190411404917e-06" rpy="0 0 0"/>
    <mass value="0.029822153915739318"/>
    <inertia ixx="2.7e-05" iyy="1.9e-05" izz="4.1e-05" ixy="0.0" iyz="-1e-06" ixz="-0.0"/>
  </inertial>
  <visual>
    <origin xyz="0.027326 -0.16362 0.009243" rpy="0 0 0"/>
    <geometry>
      <mesh filename="file://$(find antsy_description)/meshes/tibia_ml_1.stl" scale="0.001 0.001 0.001"/>
    </geometry>
    <material name="silver"/>
  </visual>
  <collision>
    <origin xyz="0.027326 -0.16362 0.009243" rpy="0 0 0"/>
    <geometry>
      <mesh filename="file://$(find antsy_description)/meshes/tibia_ml_1.stl" scale="0.001 0.001 0.001"/>
    </geometry>
  </collision>
</link>

<link name="foot_ml_1">
  <inertial>
    <origin xyz="0.0281524335431076 0.04175379913775734 -0.006856168793523123" rpy="0 0 0"/>
    <mass value="0.08076187945098641"/>
    <inertia ixx="0.000205" iyy="3.9e-05" izz="0.000199" ixy="2e-06" iyz="4.1e-05" ixz="-0.0"/>
  </inertial>
  <visual>
    <origin xyz="0.027326 -0.26362 0.009243" rpy="0 0 0"/>
    <geometry>
      <mesh filename="file://$(find antsy_description)/meshes/foot_ml_1.stl" scale="0.001 0.001 0.001"/>
    </geometry>
    <material name="silver"/>
  </visual>
  <collision>
    <origin xyz="0.027326 -0.26362 0.009243" rpy="0 0 0"/>
    <geometry>
      <mesh filename="file://$(find antsy_description)/meshes/foot_ml_1.stl" scale="0.001 0.001 0.001"/>
    </geometry>
  </collision>
</link>

<link name="coxa_fl_1">
  <inertial>
    <origin xyz="0.032192402575266954 0.017421576039831993 -0.02752364592755577" rpy="0 0 0"/>
    <mass value="0.06644962989519385"/>
    <inertia ixx="3.2e-05" iyy="3.4e-05" izz="2.4e-05" ixy="-1e-06" iyz="0.0" ixz="-0.0"/>
  </inertial>
  <visual>
    <origin xyz="-0.13712 -0.086983 -0.028208" rpy="0 0 0"/>
    <geometry>
      <mesh filename="file://$(find antsy_description)/meshes/coxa_fl_1.stl" scale="0.001 0.001 0.001"/>
    </geometry>
    <material name="silver"/>
  </visual>
  <collision>
    <origin xyz="-0.13712 -0.086983 -0.028208" rpy="0 0 0"/>
    <geometry>
      <mesh filename="file://$(find antsy_description)/meshes/coxa_fl_1.stl" scale="0.001 0.001 0.001"/>
    </geometry>
  </collision>
</link>

<link name="tibia_fl_1">
  <inertial>
    <origin xyz="0.05741244436140594 0.0015088868304491132 1.3926756694711273e-06" rpy="0 0 0"/>
    <mass value="0.029822153915739318"/>
    <inertia ixx="2.1e-05" iyy="2.5e-05" izz="4.1e-05" ixy="-3e-06" iyz="-0.0" ixz="-1e-06"/>
  </inertial>
  <visual>
    <origin xyz="-0.161085 -0.132466 0.008945" rpy="0 0 0"/>
    <geometry>
      <mesh filename="file://$(find antsy_description)/meshes/tibia_fl_1.stl" scale="0.001 0.001 0.001"/>
    </geometry>
    <material name="silver"/>
  </visual>
  <collision>
    <origin xyz="-0.161085 -0.132466 0.008945" rpy="0 0 0"/>
    <geometry>
      <mesh filename="file://$(find antsy_description)/meshes/tibia_fl_1.stl" scale="0.001 0.001 0.001"/>
    </geometry>
  </collision>
</link>

<link name="foot_fl_1">
  <inertial>
    <origin xyz="0.050235047625492635 -0.003501480531486023 -0.006863674500980405" rpy="0 0 0"/>
    <mass value="0.08076187945098641"/>
    <inertia ixx="8.2e-05" iyy="0.000162" izz="0.000199" ixy="-7.3e-05" iyz="2.1e-05" ixz="3.5e-05"/>
  </inertial>
  <visual>
    <origin xyz="-0.247687 -0.182467 0.008946" rpy="0 0 0"/>
    <geometry>
      <mesh filename="file://$(find antsy_description)/meshes/foot_fl_1.stl" scale="0.001 0.001 0.001"/>
    </geometry>
    <material name="silver"/>
  </visual>
  <collision>
    <origin xyz="-0.247687 -0.182467 0.008946" rpy="0 0 0"/>
    <geometry>
      <mesh filename="file://$(find antsy_description)/meshes/foot_fl_1.stl" scale="0.001 0.001 0.001"/>
    </geometry>
  </collision>
</link>

<link name="coxa_bl_1">
  <inertial>
    <origin xyz="-0.03117673323773862 0.019181643507883497 -0.027523113223918833" rpy="0 0 0"/>
    <mass value="0.06644962989519385"/>
    <inertia ixx="3.3e-05" iyy="3.3e-05" izz="2.4e-05" ixy="1e-06" iyz="-0.0" ixz="-0.0"/>
  </inertial>
  <visual>
    <origin xyz="0.136966 -0.086983 -0.028208" rpy="0 0 0"/>
    <geometry>
      <mesh filename="file://$(find antsy_description)/meshes/coxa_bl_1.stl" scale="0.001 0.001 0.001"/>
    </geometry>
    <material name="silver"/>
  </visual>
  <collision>
    <origin xyz="0.136966 -0.086983 -0.028208" rpy="0 0 0"/>
    <geometry>
      <mesh filename="file://$(find antsy_description)/meshes/coxa_bl_1.stl" scale="0.001 0.001 0.001"/>
    </geometry>
  </collision>
</link>

<link name="tibia_bl_1">
  <inertial>
    <origin xyz="-0.03001170919220761 0.04896654904500128 1.6394389400369025e-05" rpy="0 0 0"/>
    <mass value="0.029822153915739318"/>
    <inertia ixx="2.1e-05" iyy="2.5e-05" izz="4.1e-05" ixy="3e-06" iyz="-0.0" ixz="1e-06"/>
  </inertial>
  <visual>
    <origin xyz="0.188329 -0.085014 0.00896" rpy="0 0 0"/>
    <geometry>
      <mesh filename="file://$(find antsy_description)/meshes/tibia_bl_1.stl" scale="0.001 0.001 0.001"/>
    </geometry>
    <material name="silver"/>
  </visual>
  <collision>
    <origin xyz="0.188329 -0.085014 0.00896" rpy="0 0 0"/>
    <geometry>
      <mesh filename="file://$(find antsy_description)/meshes/tibia_bl_1.stl" scale="0.001 0.001 0.001"/>
    </geometry>
  </collision>
</link>

<link name="foot_bl_1">
  <inertial>
    <origin xyz="-0.022082140828972252 0.045258945372716713 -0.006849278491594158" rpy="0 0 0"/>
    <mass value="0.08076187945098641"/>
    <inertia ixx="7.9e-05" iyy="0.000165" izz="0.000199" ixy="7.1e-05" iyz="2e-05" ixz="-3.6e-05"/>
  </inertial>
  <visual>
    <origin xyz="0.274931 -0.135015 0.00896" rpy="0 0 0"/>
    <geometry>
      <mesh filename="file://$(find antsy_description)/meshes/foot_bl_1.stl" scale="0.001 0.001 0.001"/>
    </geometry>
    <material name="silver"/>
  </visual>
  <collision>
    <origin xyz="0.274931 -0.135015 0.00896" rpy="0 0 0"/>
    <geometry>
      <mesh filename="file://$(find antsy_description)/meshes/foot_bl_1.stl" scale="0.001 0.001 0.001"/>
    </geometry>
  </collision>
</link>

<link name="coxa_mr_1">
  <inertial>
    <origin xyz="-0.0010161741580998569 -0.036590774034150925 -0.02752380301816996" rpy="0 0 0"/>
    <mass value="0.06644962989519385"/>
    <inertia ixx="3.4e-05" iyy="3.2e-05" izz="2.4e-05" ixy="-0.0" iyz="-0.0" ixz="0.0"/>
  </inertial>
  <visual>
    <origin xyz="-7.1e-05 0.11831 -0.027918" rpy="0 0 0"/>
    <geometry>
      <mesh filename="file://$(find antsy_description)/meshes/coxa_mr_1.stl" scale="0.001 0.001 0.001"/>
    </geometry>
    <material name="silver"/>
  </visual>
  <collision>
    <origin xyz="-7.1e-05 0.11831 -0.027918" rpy="0 0 0"/>
    <geometry>
      <mesh filename="file://$(find antsy_description)/meshes/coxa_mr_1.stl" scale="0.001 0.001 0.001"/>
    </geometry>
  </collision>
</link>

<link name="tibia_mr_1">
  <inertial>
    <origin xyz="-0.027400260822124486 -0.050475484574214496 9.252190411404917e-06" rpy="0 0 0"/>
    <mass value="0.029822153915739318"/>
    <inertia ixx="2.7e-05" iyy="1.9e-05" izz="4.1e-05" ixy="0.0" iyz="1e-06" ixz="0.0"/>
  </inertial>
  <visual>
    <origin xyz="-0.027468 0.161806 0.009243" rpy="0 0 0"/>
    <geometry>
      <mesh filename="file://$(find antsy_description)/meshes/tibia_mr_1.stl" scale="0.001 0.001 0.001"/>
    </geometry>
    <material name="silver"/>
  </visual>
  <collision>
    <origin xyz="-0.027468 0.161806 0.009243" rpy="0 0 0"/>
    <geometry>
      <mesh filename="file://$(find antsy_description)/meshes/tibia_mr_1.stl" scale="0.001 0.001 0.001"/>
    </geometry>
  </collision>
</link>

<link name="foot_mr_1">
  <inertial>
    <origin xyz="-0.02815241698003511 -0.04175454988019195 -0.00685616879352312" rpy="0 0 0"/>
    <mass value="0.08076187945098641"/>
    <inertia ixx="0.000205" iyy="3.9e-05" izz="0.000199" ixy="2e-06" iyz="-4.1e-05" ixz="0.0"/>
  </inertial>
  <visual>
    <origin xyz="-0.027468 0.261806 0.009243" rpy="0 0 0"/>
    <geometry>
      <mesh filename="file://$(find antsy_description)/meshes/foot_mr_1.stl" scale="0.001 0.001 0.001"/>
    </geometry>
    <material name="silver"/>
  </visual>
  <collision>
    <origin xyz="-0.027468 0.261806 0.009243" rpy="0 0 0"/>
    <geometry>
      <mesh filename="file://$(find antsy_description)/meshes/foot_mr_1.stl" scale="0.001 0.001 0.001"/>
    </geometry>
  </collision>
</link>

<link name="coxa_fr_1">
  <inertial>
    <origin xyz="0.03117619923604431 -0.01918239425031805 -0.027523113223918816" rpy="0 0 0"/>
    <mass value="0.06644962989519385"/>
    <inertia ixx="3.3e-05" iyy="3.3e-05" izz="2.4e-05" ixy="1e-06" iyz="0.0" ixz="0.0"/>
  </inertial>
  <visual>
    <origin xyz="-0.13712 0.085169 -0.028208" rpy="0 0 0"/>
    <geometry>
      <mesh filename="file://$(find antsy_description)/meshes/coxa_fr_1.stl" scale="0.001 0.001 0.001"/>
    </geometry>
    <material name="silver"/>
  </visual>
  <collision>
    <origin xyz="-0.13712 0.085169 -0.028208" rpy="0 0 0"/>
    <geometry>
      <mesh filename="file://$(find antsy_description)/meshes/coxa_fr_1.stl" scale="0.001 0.001 0.001"/>
    </geometry>
  </collision>
</link>

<link name="tibia_fr_1">
  <inertial>
    <origin xyz="0.030012175190513385 -0.04896729978743572 1.6394389400372494e-05" rpy="0 0 0"/>
    <mass value="0.029822153915739318"/>
    <inertia ixx="2.1e-05" iyy="2.5e-05" izz="4.1e-05" ixy="3e-06" iyz="0.0" ixz="-1e-06"/>
  </inertial>
  <visual>
    <origin xyz="-0.188482 0.0832 0.00896" rpy="0 0 0"/>
    <geometry>
      <mesh filename="file://$(find antsy_description)/meshes/tibia_fr_1.stl" scale="0.001 0.001 0.001"/>
    </geometry>
    <material name="silver"/>
  </visual>
  <collision>
    <origin xyz="-0.188482 0.0832 0.00896" rpy="0 0 0"/>
    <geometry>
      <mesh filename="file://$(find antsy_description)/meshes/tibia_fr_1.stl" scale="0.001 0.001 0.001"/>
    </geometry>
  </collision>
</link>

<link name="foot_fr_1">
  <inertial>
    <origin xyz="0.022082606827277806 -0.045259696115151155 -0.006849278491594172" rpy="0 0 0"/>
    <mass value="0.08076187945098641"/>
    <inertia ixx="7.9e-05" iyy="0.000165" izz="0.000199" ixy="7.1e-05" iyz="-2e-05" ixz="3.6e-05"/>
  </inertial>
  <visual>
    <origin xyz="-0.275084 0.133201 0.00896" rpy="0 0 0"/>
    <geometry>
      <mesh filename="file://$(find antsy_description)/meshes/foot_fr_1.stl" scale="0.001 0.001 0.001"/>
    </geometry>
    <material name="silver"/>
  </visual>
  <collision>
    <origin xyz="-0.275084 0.133201 0.00896" rpy="0 0 0"/>
    <geometry>
      <mesh filename="file://$(find antsy_description)/meshes/foot_fr_1.stl" scale="0.001 0.001 0.001"/>
    </geometry>
  </collision>
</link>

<link name="coxa_br_1">
  <inertial>
    <origin xyz="-0.032192936576961595 -0.017422326782266392 -0.02752364592755585" rpy="0 0 0"/>
    <mass value="0.06644962989519385"/>
    <inertia ixx="3.2e-05" iyy="3.4e-05" izz="2.4e-05" ixy="-1e-06" iyz="-0.0" ixz="0.0"/>
  </inertial>
  <visual>
    <origin xyz="0.136966 0.085169 -0.028208" rpy="0 0 0"/>
    <geometry>
      <mesh filename="file://$(find antsy_description)/meshes/coxa_br_1.stl" scale="0.001 0.001 0.001"/>
    </geometry>
    <material name="silver"/>
  </visual>
  <collision>
    <origin xyz="0.136966 0.085169 -0.028208" rpy="0 0 0"/>
    <geometry>
      <mesh filename="file://$(find antsy_description)/meshes/coxa_br_1.stl" scale="0.001 0.001 0.001"/>
    </geometry>
  </collision>
</link>

<link name="tibia_br_1">
  <inertial>
    <origin xyz="-0.05741297836310025 -0.0015086375728834978 1.3926756693583703e-06" rpy="0 0 0"/>
    <mass value="0.029822153915739318"/>
    <inertia ixx="2.1e-05" iyy="2.5e-05" izz="4.1e-05" ixy="-3e-06" iyz="0.0" ixz="1e-06"/>
  </inertial>
  <visual>
    <origin xyz="0.160931 0.130653 0.008945" rpy="0 0 0"/>
    <geometry>
      <mesh filename="file://$(find antsy_description)/meshes/tibia_br_1.stl" scale="0.001 0.001 0.001"/>
    </geometry>
    <material name="silver"/>
  </visual>
  <collision>
    <origin xyz="0.160931 0.130653 0.008945" rpy="0 0 0"/>
    <geometry>
      <mesh filename="file://$(find antsy_description)/meshes/tibia_br_1.stl" scale="0.001 0.001 0.001"/>
    </geometry>
  </collision>
</link>

<link name="foot_br_1">
  <inertial>
    <origin xyz="-0.05023558162718694 0.0035017297890517496 -0.006863674500980509" rpy="0 0 0"/>
    <mass value="0.08076187945098641"/>
    <inertia ixx="8.2e-05" iyy="0.000162" izz="0.000199" ixy="-7.3e-05" iyz="-2.1e-05" ixz="-3.5e-05"/>
  </inertial>
  <visual>
    <origin xyz="0.247533 0.180654 0.008946" rpy="0 0 0"/>
    <geometry>
      <mesh filename="file://$(find antsy_description)/meshes/foot_br_1.stl" scale="0.001 0.001 0.001"/>
    </geometry>
    <material name="silver"/>
  </visual>
  <collision>
    <origin xyz="0.247533 0.180654 0.008946" rpy="0 0 0"/>
    <geometry>
      <mesh filename="file://$(find antsy_description)/meshes/foot_br_1.stl" scale="0.001 0.001 0.001"/>
    </geometry>
  </collision>
</link>

<joint name="base_to_coxa_ml" type="revolute">
  <origin xyz="7.1e-05 0.120123 0.027918" rpy="0 0 0"/>
  <parent link="base_link"/>
  <child link="coxa_ml_1"/>
  <axis xyz="-0.0 -0.006981 0.999976"/>
  <limit upper="1.570796" lower="-1.570796" effort="100" velocity="100"/>
</joint>

<joint name="coxa_ml_to_tibia_ml" type="revolute">
  <origin xyz="-0.027397 0.043497 -0.037161" rpy="0 0 0"/>
  <parent link="coxa_ml_1"/>
  <child link="tibia_ml_1"/>
  <axis xyz="-1.0 -0.0 -0.000329"/>
  <limit upper="2.007129" lower="-1.308997" effort="100" velocity="100"/>
</joint>

<joint name="tibia_ml_to_foot_ml" type="revolute">
  <origin xyz="0.0 0.1 0.0" rpy="0 0 0"/>
  <parent link="tibia_ml_1"/>
  <child link="foot_ml_1"/>
  <axis xyz="-1.0 -0.0 -0.000329"/>
  <limit upper="2.356194" lower="-2.094395" effort="100" velocity="100"/>
</joint>

<joint name="base_to_coxa_fl" type="revolute">
  <origin xyz="0.13712 0.086983 0.028208" rpy="0 0 0"/>
  <parent link="base_link"/>
  <child link="coxa_fl_1"/>
  <axis xyz="0.005911 0.003715 -0.999976"/>
  <limit upper="1.570796" lower="-1.570796" effort="100" velocity="100"/>
</joint>

<joint name="coxa_fl_to_tibia_fl" type="revolute">
  <origin xyz="0.023965 0.045483 -0.037153" rpy="0 0 0"/>
  <parent link="coxa_fl_1"/>
  <child link="tibia_fl_1"/>
  <axis xyz="-0.50001 0.866019 -6.7e-05"/>
  <limit upper="2.007129" lower="-1.308997" effort="100" velocity="100"/>
</joint>

<joint name="tibia_fl_to_foot_fl" type="revolute">
  <origin xyz="0.086602 0.050001 -1e-06" rpy="0 0 0"/>
  <parent link="tibia_fl_1"/>
  <child link="foot_fl_1"/>
  <axis xyz="-0.50001 0.866019 -6.7e-05"/>
  <limit upper="2.356194" lower="-2.094395" effort="100" velocity="100"/>
</joint>

<joint name="base_to_coxa_bl" type="revolute">
  <origin xyz="-0.136966 0.086983 0.028208" rpy="0 0 0"/>
  <parent link="base_link"/>
  <child link="coxa_bl_1"/>
  <axis xyz="0.005911 -0.003715 0.999976"/>
  <limit upper="1.570796" lower="-1.570796" effort="100" velocity="100"/>
</joint>

<joint name="coxa_bl_to_tibia_bl" type="revolute">
  <origin xyz="-0.051363 -0.001969 -0.037168" rpy="0 0 0"/>
  <parent link="coxa_bl_1"/>
  <child link="tibia_bl_1"/>
  <axis xyz="-0.50001 -0.866019 -0.000591"/>
  <limit upper="2.007129" lower="-1.308997" effort="100" velocity="100"/>
</joint>

<joint name="tibia_bl_to_foot_bl" type="revolute">
  <origin xyz="-0.086602 0.050001 0.0" rpy="0 0 0"/>
  <parent link="tibia_bl_1"/>
  <child link="foot_bl_1"/>
  <axis xyz="-0.50001 -0.866019 -0.000591"/>
  <limit upper="2.356194" lower="-2.094395" effort="100" velocity="100"/>
</joint>

<joint name="base_mr_to_coxa_mr" type="revolute">
  <origin xyz="7.1e-05 -0.11831 0.027918" rpy="0 0 0"/>
  <parent link="base_link"/>
  <child link="coxa_mr_1"/>
  <axis xyz="0.0 0.006981 0.999976"/>
  <limit upper="1.570796" lower="-1.570796" effort="100" velocity="100"/>
</joint>

<joint name="coxa_mr_to_tibia_mr" type="revolute">
  <origin xyz="0.027397 -0.043496 -0.037161" rpy="0 0 0"/>
  <parent link="coxa_mr_1"/>
  <child link="tibia_mr_1"/>
  <axis xyz="1.0 0.0 -0.000329"/>
  <limit upper="2.007129" lower="-1.308997" effort="100" velocity="100"/>
</joint>

<joint name="tibia_mr_to_foot_mr" type="revolute">
  <origin xyz="0.0 -0.1 0.0" rpy="0 0 0"/>
  <parent link="tibia_mr_1"/>
  <child link="foot_mr_1"/>
  <axis xyz="1.0 -0.0 -0.000329"/>
  <limit upper="2.356194" lower="-2.094395" effort="100" velocity="100"/>
</joint>

<joint name="base_to_coxa_fr" type="revolute">
  <origin xyz="0.13712 -0.085169 0.028208" rpy="0 0 0"/>
  <parent link="base_link"/>
  <child link="coxa_fr_1"/>
  <axis xyz="-0.005911 0.003715 0.999976"/>
  <limit upper="1.570796" lower="-1.570796" effort="100" velocity="100"/>
</joint>

<joint name="coxa_fr_to_tibia_fr" type="revolute">
  <origin xyz="0.051362 0.001969 -0.037168" rpy="0 0 0"/>
  <parent link="coxa_fr_1"/>
  <child link="tibia_fr_1"/>
  <axis xyz="0.50001 0.866019 -0.000591"/>
  <limit upper="2.007129" lower="-1.308997" effort="100" velocity="100"/>
</joint>

<joint name="tibia_fr_to_foot_fr" type="revolute">
  <origin xyz="0.086602 -0.050001 0.0" rpy="0 0 0"/>
  <parent link="tibia_fr_1"/>
  <child link="foot_fr_1"/>
  <axis xyz="0.50001 0.866019 -0.000591"/>
  <limit upper="2.356194" lower="-2.094395" effort="100" velocity="100"/>
</joint>

<joint name="base_to_coxa_br" type="revolute">
  <origin xyz="-0.136966 -0.085169 0.028208" rpy="0 0 0"/>
  <parent link="base_link"/>
  <child link="coxa_br_1"/>
  <axis xyz="0.005911 0.003715 0.999976"/>
  <limit upper="1.570796" lower="-1.570796" effort="100" velocity="100"/>
</joint>

<joint name="coxa_br_to_tibia_br" type="revolute">
  <origin xyz="-0.023965 -0.045484 -0.037153" rpy="0 0 0"/>
  <parent link="coxa_br_1"/>
  <child link="tibia_br_1"/>
  <axis xyz="0.50001 -0.866019 -6.7e-05"/>
  <limit upper="2.007129" lower="-1.308997" effort="100" velocity="100"/>
</joint>

<joint name="tibia_br_to_foot_br" type="revolute">
  <origin xyz="-0.086602 -0.050001 -1e-06" rpy="0 0 0"/>
  <parent link="tibia_br_1"/>
  <child link="foot_br_1"/>
  <axis xyz="0.50001 -0.866019 -6.7e-05"/>
  <limit upper="2.356194" lower="-2.094395" effort="100" velocity="100"/>
</joint>

</robot>
