<?xml version="1.0" ?>
<!-- =================================================================================== -->
<!-- |    This document was autogenerated by xacro from antsy_description.xacro        | -->
<!-- |    EDITING THIS FILE BY HAND IS NOT RECOMMENDED                                 | -->
<!-- =================================================================================== -->
<robot name="hexapod">
  <!-- ********* -->
  <!-- Materials -->
  <!-- ********* -->
  <material name="frame">
    <color rgba="1.0 0.6 0.0 1"/>
  </material>
  <material name="feet">
    <color rgba="0.33 0.45 1.0 1"/>
  </material>
  <!-- datasheet tells 5.81 -->
  <!-- <xacro:property name="servo_velocity_limit" value="5.6" /> -->
  <!-- base_footprint -->
  <link name="base_footprint"/>
  <joint name="base_footprint_joint" type="fixed">
    <parent link="base_footprint"/>
    <child link="base_link"/>
  </joint>
  <!-- base_link -->
  <link name="base_link">
    <visual>
      <origin rpy="0 0 1.5707963267948966" xyz="0 0 0"/>
      <geometry>
        <mesh filename="file:///home/laroto/antsy/install/antsy_description/share/antsy_description/meshes/simple_meshes/frame_simple.stl" scale="0.001 0.001 0.001"/>
      </geometry>
      <material name="frame"/>
    </visual>
    <collision>
      <geometry>
        <box size="0.300 0.200 0.050"/>
      </geometry>
    </collision>
    <inertial>
      <origin rpy="0 0 0" xyz="0.00014120578374947324 0.000907462590201314 -0.0004863329579636028"/>
      <mass value="0.9"/>
      <!-- changed from  6.980366975019921 -->
      <inertia ixx="0.035507" ixy="8e-06" ixz="-1.7e-05" iyy="0.050259" iyz="4e-06" izz="0.082758"/>
    </inertial>
  </link>
  <!-- leg_X: fixed to base_link -->
  <link name="leg_0"/>
  <joint name="base_link__leg_0" type="fixed">
    <parent link="base_link"/>
    <child link="leg_0"/>
    <origin rpy="0 0 0.5235963267948966" xyz=" 0.138  0.0875 0.0"/>
  </joint>
  <!-- leg_Xa: shoulder  -->
  <link name="leg_0a">
    <visual>
      <origin rpy="0 0 0" xyz="0 0 0"/>
      <geometry>
        <mesh filename="file:///home/laroto/antsy/install/antsy_description/share/antsy_description/meshes/simple_meshes/coxa_simple.stl" scale="0.001 0.001 0.001"/>
      </geometry>
      <material name="feet"/>
    </visual>
    <collision>
      <origin xyz="0.021875 0.05 0.05"/>
      <geometry>
        <box size="0.04375 0.05 0.05"/>
      </geometry>
    </collision>
    <inertial>
      <mass value="0.09"/>
      <!-- changed from 0.06644962989519385 -->
      <origin xyz="0.021875 0 0"/>
      <inertia ixx="3.4e-05" ixy="-0.0" ixz="-0.0" iyy="3.2e-05" iyz="0.0" izz="2.4e-05"/>
    </inertial>
  </link>
  <joint name="leg_0_base__leg_0a" type="revolute">
    <axis xyz="0 0 1"/>
    <limit effort="4.25" lower="-1.5708" upper="1.5708" velocity="110.2"/>
    <parent link="leg_0"/>
    <child link="leg_0a"/>
    <dynamics damping="0.1" friction="0.3"/>
  </joint>
  <!-- leg_Xb: upper segment -->
  <link name="leg_0b">
    <visual>
      <origin xyz="0 0 0"/>
      <geometry>
        <mesh filename="file:///home/laroto/antsy/install/antsy_description/share/antsy_description/meshes/simple_meshes/tibia_simple.stl" scale="0.001 0.001 0.001"/>
      </geometry>
      <material name="feet"/>
    </visual>
    <collision>
      <origin xyz="0.05 0 0"/>
      <geometry>
        <box size="0.1 0.06 0.025"/>
      </geometry>
    </collision>
    <inertial>
      <mass value="0.08"/>
      <!-- changed from 0.029822153915739318 -->
      <origin xyz="0.05 0 0"/>
      <inertia ixx="2.7e-05" ixy="0.0" ixz="-0.0" iyy="1.9e-05" iyz="-1e-06" izz="4.1e-05"/>
    </inertial>
  </link>
  <joint name="leg_0a__leg_0b" type="revolute">
    <axis xyz="0 -1 0"/>
    <limit effort="4.25" lower="-1.309" upper="2.00713" velocity="110.2"/>
    <parent link="leg_0a"/>
    <child link="leg_0b"/>
    <origin xyz="0.04375 0 -0.010"/>
    <dynamics damping="0.1" friction="0.3"/>
  </joint>
  <!-- leg_Xc: lower segment -->
  <link name="leg_0c">
    <visual>
      <origin rpy="0 -0.35 0" xyz="0 0 0"/>
      <geometry>
        <mesh filename="file:///home/laroto/antsy/install/antsy_description/share/antsy_description/meshes/simple_meshes/foot_simple.stl" scale="0.001 0.001 0.001"/>
      </geometry>
      <material name="feet"/>
    </visual>
    <visual>
      <origin xyz="0.15 0 0"/>
      <geometry>
        <sphere radius="0.0075"/>
      </geometry>
      <material name="feet"/>
    </visual>
    <collision>
      <origin xyz="0.075 0 0"/>
      <geometry>
        <box size="0.15 0.045 0.05"/>
      </geometry>
    </collision>
    <collision>
      <origin xyz="0.15 0 0"/>
      <geometry>
        <sphere radius="0.0075"/>
      </geometry>
      <contact_coefficients mu="0.7"/>
    </collision>
    <inertial>
      <mass value="0.030"/>
      <!-- changed from 0.08076187945098641 -->
      <origin rpy="0 -0.35 0" xyz="0.075 0 0"/>
      <inertia ixx="0.000205" ixy="2e-06" ixz="-0.0" iyy="3.9e-05" iyz="4.1e-05" izz="0.000199"/>
    </inertial>
  </link>
  <joint name="leg_0b__leg_0c" type="revolute">
    <axis xyz="0 1 0"/>
    <limit effort="4.25" lower="-2.0944" upper="2.35619" velocity="110.2"/>
    <parent link="leg_0b"/>
    <child link="leg_0c"/>
    <origin rpy="0 0.35 0" xyz="0.1 0 0"/>
    <dynamics damping="0.1" friction="0.3"/>
  </joint>
  <!-- Link in the foot ball center to easily refer to that point in KDL -->
  <link name="foot_0"/>
  <joint name="leg_0c__foot_0" type="fixed">
    <parent link="leg_0c"/>
    <child link="foot_0"/>
    <origin rpy="0 0.4 0" xyz="0.15 0 0"/>
  </joint>
  <gazebo>
    <plugin filename="gz-sim-joint-position-controller-system" name="gz::sim::systems::JointPositionController">
      <joint_name>leg_0_base__leg_0a</joint_name>
      <use_actuator_msg>true</use_actuator_msg>
      <actuator_number>0</actuator_number>
      <cmd_max>4.25</cmd_max>
      <cmd_min>-4.25</cmd_min>
      <p_gain>17.8</p_gain>
      <i_gain>0.</i_gain>
      <d_gain>0.</d_gain>
    </plugin>
  </gazebo>
  <gazebo>
    <plugin filename="gz-sim-joint-position-controller-system" name="gz::sim::systems::JointPositionController">
      <joint_name>leg_0a__leg_0b</joint_name>
      <use_actuator_msg>true</use_actuator_msg>
      <actuator_number>1</actuator_number>
      <cmd_max>4.25</cmd_max>
      <cmd_min>-4.25</cmd_min>
      <p_gain>17.8</p_gain>
      <i_gain>0.</i_gain>
      <d_gain>0.</d_gain>
    </plugin>
  </gazebo>
  <gazebo>
    <plugin filename="gz-sim-joint-position-controller-system" name="gz::sim::systems::JointPositionController">
      <joint_name>leg_0b__leg_0c</joint_name>
      <use_actuator_msg>true</use_actuator_msg>
      <actuator_number>2</actuator_number>
      <cmd_max>4.25</cmd_max>
      <cmd_min>-4.25</cmd_min>
      <p_gain>17.8</p_gain>
      <i_gain>0.</i_gain>
      <d_gain>0.</d_gain>
    </plugin>
  </gazebo>
  <!-- leg_X: fixed to base_link -->
  <link name="leg_1"/>
  <joint name="base_link__leg_1" type="fixed">
    <parent link="base_link"/>
    <child link="leg_1"/>
    <origin rpy="0 0 1.5707963267948966" xyz=" 0.00  0.11950 0.0"/>
  </joint>
  <!-- leg_Xa: shoulder  -->
  <link name="leg_1a">
    <visual>
      <origin rpy="0 0 0" xyz="0 0 0"/>
      <geometry>
        <mesh filename="file:///home/laroto/antsy/install/antsy_description/share/antsy_description/meshes/simple_meshes/coxa_simple.stl" scale="0.001 0.001 0.001"/>
      </geometry>
      <material name="feet"/>
    </visual>
    <collision>
      <origin xyz="0.021875 0.05 0.05"/>
      <geometry>
        <box size="0.04375 0.05 0.05"/>
      </geometry>
    </collision>
    <inertial>
      <mass value="0.09"/>
      <!-- changed from 0.06644962989519385 -->
      <origin xyz="0.021875 0 0"/>
      <inertia ixx="3.4e-05" ixy="-0.0" ixz="-0.0" iyy="3.2e-05" iyz="0.0" izz="2.4e-05"/>
    </inertial>
  </link>
  <joint name="leg_1_base__leg_1a" type="revolute">
    <axis xyz="0 0 1"/>
    <limit effort="4.25" lower="-1.5708" upper="1.5708" velocity="110.2"/>
    <parent link="leg_1"/>
    <child link="leg_1a"/>
    <dynamics damping="0.1" friction="0.3"/>
  </joint>
  <!-- leg_Xb: upper segment -->
  <link name="leg_1b">
    <visual>
      <origin xyz="0 0 0"/>
      <geometry>
        <mesh filename="file:///home/laroto/antsy/install/antsy_description/share/antsy_description/meshes/simple_meshes/tibia_simple.stl" scale="0.001 0.001 0.001"/>
      </geometry>
      <material name="feet"/>
    </visual>
    <collision>
      <origin xyz="0.05 0 0"/>
      <geometry>
        <box size="0.1 0.06 0.025"/>
      </geometry>
    </collision>
    <inertial>
      <mass value="0.08"/>
      <!-- changed from 0.029822153915739318 -->
      <origin xyz="0.05 0 0"/>
      <inertia ixx="2.7e-05" ixy="0.0" ixz="-0.0" iyy="1.9e-05" iyz="-1e-06" izz="4.1e-05"/>
    </inertial>
  </link>
  <joint name="leg_1a__leg_1b" type="revolute">
    <axis xyz="0 -1 0"/>
    <limit effort="4.25" lower="-1.309" upper="2.00713" velocity="110.2"/>
    <parent link="leg_1a"/>
    <child link="leg_1b"/>
    <origin xyz="0.04375 0 -0.010"/>
    <dynamics damping="0.1" friction="0.3"/>
  </joint>
  <!-- leg_Xc: lower segment -->
  <link name="leg_1c">
    <visual>
      <origin rpy="0 -0.35 0" xyz="0 0 0"/>
      <geometry>
        <mesh filename="file:///home/laroto/antsy/install/antsy_description/share/antsy_description/meshes/simple_meshes/foot_simple.stl" scale="0.001 0.001 0.001"/>
      </geometry>
      <material name="feet"/>
    </visual>
    <visual>
      <origin xyz="0.15 0 0"/>
      <geometry>
        <sphere radius="0.0075"/>
      </geometry>
      <material name="feet"/>
    </visual>
    <collision>
      <origin xyz="0.075 0 0"/>
      <geometry>
        <box size="0.15 0.045 0.05"/>
      </geometry>
    </collision>
    <collision>
      <origin xyz="0.15 0 0"/>
      <geometry>
        <sphere radius="0.0075"/>
      </geometry>
      <contact_coefficients mu="0.7"/>
    </collision>
    <inertial>
      <mass value="0.030"/>
      <!-- changed from 0.08076187945098641 -->
      <origin rpy="0 -0.35 0" xyz="0.075 0 0"/>
      <inertia ixx="0.000205" ixy="2e-06" ixz="-0.0" iyy="3.9e-05" iyz="4.1e-05" izz="0.000199"/>
    </inertial>
  </link>
  <joint name="leg_1b__leg_1c" type="revolute">
    <axis xyz="0 1 0"/>
    <limit effort="4.25" lower="-2.0944" upper="2.35619" velocity="110.2"/>
    <parent link="leg_1b"/>
    <child link="leg_1c"/>
    <origin rpy="0 0.35 0" xyz="0.1 0 0"/>
    <dynamics damping="0.1" friction="0.3"/>
  </joint>
  <!-- Link in the foot ball center to easily refer to that point in KDL -->
  <link name="foot_1"/>
  <joint name="leg_1c__foot_1" type="fixed">
    <parent link="leg_1c"/>
    <child link="foot_1"/>
    <origin rpy="0 0.4 0" xyz="0.15 0 0"/>
  </joint>
  <gazebo>
    <plugin filename="gz-sim-joint-position-controller-system" name="gz::sim::systems::JointPositionController">
      <joint_name>leg_1_base__leg_1a</joint_name>
      <use_actuator_msg>true</use_actuator_msg>
      <actuator_number>3</actuator_number>
      <cmd_max>4.25</cmd_max>
      <cmd_min>-4.25</cmd_min>
      <p_gain>17.8</p_gain>
      <i_gain>0.</i_gain>
      <d_gain>0.</d_gain>
    </plugin>
  </gazebo>
  <gazebo>
    <plugin filename="gz-sim-joint-position-controller-system" name="gz::sim::systems::JointPositionController">
      <joint_name>leg_1a__leg_1b</joint_name>
      <use_actuator_msg>true</use_actuator_msg>
      <actuator_number>4</actuator_number>
      <cmd_max>4.25</cmd_max>
      <cmd_min>-4.25</cmd_min>
      <p_gain>17.8</p_gain>
      <i_gain>0.</i_gain>
      <d_gain>0.</d_gain>
    </plugin>
  </gazebo>
  <gazebo>
    <plugin filename="gz-sim-joint-position-controller-system" name="gz::sim::systems::JointPositionController">
      <joint_name>leg_1b__leg_1c</joint_name>
      <use_actuator_msg>true</use_actuator_msg>
      <actuator_number>5</actuator_number>
      <cmd_max>4.25</cmd_max>
      <cmd_min>-4.25</cmd_min>
      <p_gain>17.8</p_gain>
      <i_gain>0.</i_gain>
      <d_gain>0.</d_gain>
    </plugin>
  </gazebo>
  <!-- leg_X: fixed to base_link -->
  <link name="leg_2"/>
  <joint name="base_link__leg_2" type="fixed">
    <parent link="base_link"/>
    <child link="leg_2"/>
    <origin rpy="0 0 2.6179963267948967" xyz="-0.138  0.0875 0.0"/>
  </joint>
  <!-- leg_Xa: shoulder  -->
  <link name="leg_2a">
    <visual>
      <origin rpy="0 0 0" xyz="0 0 0"/>
      <geometry>
        <mesh filename="file:///home/laroto/antsy/install/antsy_description/share/antsy_description/meshes/simple_meshes/coxa_simple.stl" scale="0.001 0.001 0.001"/>
      </geometry>
      <material name="feet"/>
    </visual>
    <collision>
      <origin xyz="0.021875 0.05 0.05"/>
      <geometry>
        <box size="0.04375 0.05 0.05"/>
      </geometry>
    </collision>
    <inertial>
      <mass value="0.09"/>
      <!-- changed from 0.06644962989519385 -->
      <origin xyz="0.021875 0 0"/>
      <inertia ixx="3.4e-05" ixy="-0.0" ixz="-0.0" iyy="3.2e-05" iyz="0.0" izz="2.4e-05"/>
    </inertial>
  </link>
  <joint name="leg_2_base__leg_2a" type="revolute">
    <axis xyz="0 0 1"/>
    <limit effort="4.25" lower="-1.5708" upper="1.5708" velocity="110.2"/>
    <parent link="leg_2"/>
    <child link="leg_2a"/>
    <dynamics damping="0.1" friction="0.3"/>
  </joint>
  <!-- leg_Xb: upper segment -->
  <link name="leg_2b">
    <visual>
      <origin xyz="0 0 0"/>
      <geometry>
        <mesh filename="file:///home/laroto/antsy/install/antsy_description/share/antsy_description/meshes/simple_meshes/tibia_simple.stl" scale="0.001 0.001 0.001"/>
      </geometry>
      <material name="feet"/>
    </visual>
    <collision>
      <origin xyz="0.05 0 0"/>
      <geometry>
        <box size="0.1 0.06 0.025"/>
      </geometry>
    </collision>
    <inertial>
      <mass value="0.08"/>
      <!-- changed from 0.029822153915739318 -->
      <origin xyz="0.05 0 0"/>
      <inertia ixx="2.7e-05" ixy="0.0" ixz="-0.0" iyy="1.9e-05" iyz="-1e-06" izz="4.1e-05"/>
    </inertial>
  </link>
  <joint name="leg_2a__leg_2b" type="revolute">
    <axis xyz="0 -1 0"/>
    <limit effort="4.25" lower="-1.309" upper="2.00713" velocity="110.2"/>
    <parent link="leg_2a"/>
    <child link="leg_2b"/>
    <origin xyz="0.04375 0 -0.010"/>
    <dynamics damping="0.1" friction="0.3"/>
  </joint>
  <!-- leg_Xc: lower segment -->
  <link name="leg_2c">
    <visual>
      <origin rpy="0 -0.35 0" xyz="0 0 0"/>
      <geometry>
        <mesh filename="file:///home/laroto/antsy/install/antsy_description/share/antsy_description/meshes/simple_meshes/foot_simple.stl" scale="0.001 0.001 0.001"/>
      </geometry>
      <material name="feet"/>
    </visual>
    <visual>
      <origin xyz="0.15 0 0"/>
      <geometry>
        <sphere radius="0.0075"/>
      </geometry>
      <material name="feet"/>
    </visual>
    <collision>
      <origin xyz="0.075 0 0"/>
      <geometry>
        <box size="0.15 0.045 0.05"/>
      </geometry>
    </collision>
    <collision>
      <origin xyz="0.15 0 0"/>
      <geometry>
        <sphere radius="0.0075"/>
      </geometry>
      <contact_coefficients mu="0.7"/>
    </collision>
    <inertial>
      <mass value="0.030"/>
      <!-- changed from 0.08076187945098641 -->
      <origin rpy="0 -0.35 0" xyz="0.075 0 0"/>
      <inertia ixx="0.000205" ixy="2e-06" ixz="-0.0" iyy="3.9e-05" iyz="4.1e-05" izz="0.000199"/>
    </inertial>
  </link>
  <joint name="leg_2b__leg_2c" type="revolute">
    <axis xyz="0 1 0"/>
    <limit effort="4.25" lower="-2.0944" upper="2.35619" velocity="110.2"/>
    <parent link="leg_2b"/>
    <child link="leg_2c"/>
    <origin rpy="0 0.35 0" xyz="0.1 0 0"/>
    <dynamics damping="0.1" friction="0.3"/>
  </joint>
  <!-- Link in the foot ball center to easily refer to that point in KDL -->
  <link name="foot_2"/>
  <joint name="leg_2c__foot_2" type="fixed">
    <parent link="leg_2c"/>
    <child link="foot_2"/>
    <origin rpy="0 0.4 0" xyz="0.15 0 0"/>
  </joint>
  <gazebo>
    <plugin filename="gz-sim-joint-position-controller-system" name="gz::sim::systems::JointPositionController">
      <joint_name>leg_2_base__leg_2a</joint_name>
      <use_actuator_msg>true</use_actuator_msg>
      <actuator_number>6</actuator_number>
      <cmd_max>4.25</cmd_max>
      <cmd_min>-4.25</cmd_min>
      <p_gain>17.8</p_gain>
      <i_gain>0.</i_gain>
      <d_gain>0.</d_gain>
    </plugin>
  </gazebo>
  <gazebo>
    <plugin filename="gz-sim-joint-position-controller-system" name="gz::sim::systems::JointPositionController">
      <joint_name>leg_2a__leg_2b</joint_name>
      <use_actuator_msg>true</use_actuator_msg>
      <actuator_number>7</actuator_number>
      <cmd_max>4.25</cmd_max>
      <cmd_min>-4.25</cmd_min>
      <p_gain>17.8</p_gain>
      <i_gain>0.</i_gain>
      <d_gain>0.</d_gain>
    </plugin>
  </gazebo>
  <gazebo>
    <plugin filename="gz-sim-joint-position-controller-system" name="gz::sim::systems::JointPositionController">
      <joint_name>leg_2b__leg_2c</joint_name>
      <use_actuator_msg>true</use_actuator_msg>
      <actuator_number>8</actuator_number>
      <cmd_max>4.25</cmd_max>
      <cmd_min>-4.25</cmd_min>
      <p_gain>17.8</p_gain>
      <i_gain>0.</i_gain>
      <d_gain>0.</d_gain>
    </plugin>
  </gazebo>
  <!-- leg_X: fixed to base_link -->
  <link name="leg_3"/>
  <joint name="base_link__leg_3" type="fixed">
    <parent link="base_link"/>
    <child link="leg_3"/>
    <origin rpy="0 0 -2.6179963267948967" xyz="-0.138 -0.0875 0.0"/>
  </joint>
  <!-- leg_Xa: shoulder  -->
  <link name="leg_3a">
    <visual>
      <origin rpy="0 0 0" xyz="0 0 0"/>
      <geometry>
        <mesh filename="file:///home/laroto/antsy/install/antsy_description/share/antsy_description/meshes/simple_meshes/coxa_simple.stl" scale="0.001 0.001 0.001"/>
      </geometry>
      <material name="feet"/>
    </visual>
    <collision>
      <origin xyz="0.021875 0.05 0.05"/>
      <geometry>
        <box size="0.04375 0.05 0.05"/>
      </geometry>
    </collision>
    <inertial>
      <mass value="0.09"/>
      <!-- changed from 0.06644962989519385 -->
      <origin xyz="0.021875 0 0"/>
      <inertia ixx="3.4e-05" ixy="-0.0" ixz="-0.0" iyy="3.2e-05" iyz="0.0" izz="2.4e-05"/>
    </inertial>
  </link>
  <joint name="leg_3_base__leg_3a" type="revolute">
    <axis xyz="0 0 1"/>
    <limit effort="4.25" lower="-1.5708" upper="1.5708" velocity="110.2"/>
    <parent link="leg_3"/>
    <child link="leg_3a"/>
    <dynamics damping="0.1" friction="0.3"/>
  </joint>
  <!-- leg_Xb: upper segment -->
  <link name="leg_3b">
    <visual>
      <origin xyz="0 0 0"/>
      <geometry>
        <mesh filename="file:///home/laroto/antsy/install/antsy_description/share/antsy_description/meshes/simple_meshes/tibia_simple.stl" scale="0.001 0.001 0.001"/>
      </geometry>
      <material name="feet"/>
    </visual>
    <collision>
      <origin xyz="0.05 0 0"/>
      <geometry>
        <box size="0.1 0.06 0.025"/>
      </geometry>
    </collision>
    <inertial>
      <mass value="0.08"/>
      <!-- changed from 0.029822153915739318 -->
      <origin xyz="0.05 0 0"/>
      <inertia ixx="2.7e-05" ixy="0.0" ixz="-0.0" iyy="1.9e-05" iyz="-1e-06" izz="4.1e-05"/>
    </inertial>
  </link>
  <joint name="leg_3a__leg_3b" type="revolute">
    <axis xyz="0 1 0"/>
    <limit effort="4.25" lower="-1.309" upper="2.00713" velocity="110.2"/>
    <parent link="leg_3a"/>
    <child link="leg_3b"/>
    <origin xyz="0.04375 0 -0.010"/>
    <dynamics damping="0.1" friction="0.3"/>
  </joint>
  <!-- leg_Xc: lower segment -->
  <link name="leg_3c">
    <visual>
      <origin rpy="0 -0.35 0" xyz="0 0 0"/>
      <geometry>
        <mesh filename="file:///home/laroto/antsy/install/antsy_description/share/antsy_description/meshes/simple_meshes/foot_simple.stl" scale="0.001 0.001 0.001"/>
      </geometry>
      <material name="feet"/>
    </visual>
    <visual>
      <origin xyz="0.15 0 0"/>
      <geometry>
        <sphere radius="0.0075"/>
      </geometry>
      <material name="feet"/>
    </visual>
    <collision>
      <origin xyz="0.075 0 0"/>
      <geometry>
        <box size="0.15 0.045 0.05"/>
      </geometry>
    </collision>
    <collision>
      <origin xyz="0.15 0 0"/>
      <geometry>
        <sphere radius="0.0075"/>
      </geometry>
      <contact_coefficients mu="0.7"/>
    </collision>
    <inertial>
      <mass value="0.030"/>
      <!-- changed from 0.08076187945098641 -->
      <origin rpy="0 -0.35 0" xyz="0.075 0 0"/>
      <inertia ixx="0.000205" ixy="2e-06" ixz="-0.0" iyy="3.9e-05" iyz="4.1e-05" izz="0.000199"/>
    </inertial>
  </link>
  <joint name="leg_3b__leg_3c" type="revolute">
    <axis xyz="0 -1 0"/>
    <limit effort="4.25" lower="-2.0944" upper="2.35619" velocity="110.2"/>
    <parent link="leg_3b"/>
    <child link="leg_3c"/>
    <origin rpy="0 0.35 0" xyz="0.1 0 0"/>
    <dynamics damping="0.1" friction="0.3"/>
  </joint>
  <!-- Link in the foot ball center to easily refer to that point in KDL -->
  <link name="foot_3"/>
  <joint name="leg_3c__foot_3" type="fixed">
    <parent link="leg_3c"/>
    <child link="foot_3"/>
    <origin rpy="0 0.4 0" xyz="0.15 0 0"/>
  </joint>
  <gazebo>
    <plugin filename="gz-sim-joint-position-controller-system" name="gz::sim::systems::JointPositionController">
      <joint_name>leg_3_base__leg_3a</joint_name>
      <use_actuator_msg>true</use_actuator_msg>
      <actuator_number>9</actuator_number>
      <cmd_max>4.25</cmd_max>
      <cmd_min>-4.25</cmd_min>
      <p_gain>17.8</p_gain>
      <i_gain>0.</i_gain>
      <d_gain>0.</d_gain>
    </plugin>
  </gazebo>
  <gazebo>
    <plugin filename="gz-sim-joint-position-controller-system" name="gz::sim::systems::JointPositionController">
      <joint_name>leg_3a__leg_3b</joint_name>
      <use_actuator_msg>true</use_actuator_msg>
      <actuator_number>10</actuator_number>
      <cmd_max>4.25</cmd_max>
      <cmd_min>-4.25</cmd_min>
      <p_gain>17.8</p_gain>
      <i_gain>0.</i_gain>
      <d_gain>0.</d_gain>
    </plugin>
  </gazebo>
  <gazebo>
    <plugin filename="gz-sim-joint-position-controller-system" name="gz::sim::systems::JointPositionController">
      <joint_name>leg_3b__leg_3c</joint_name>
      <use_actuator_msg>true</use_actuator_msg>
      <actuator_number>11</actuator_number>
      <cmd_max>4.25</cmd_max>
      <cmd_min>-4.25</cmd_min>
      <p_gain>17.8</p_gain>
      <i_gain>0.</i_gain>
      <d_gain>0.</d_gain>
    </plugin>
  </gazebo>
  <!-- leg_X: fixed to base_link -->
  <link name="leg_4"/>
  <joint name="base_link__leg_4" type="fixed">
    <parent link="base_link"/>
    <child link="leg_4"/>
    <origin rpy="0 0 -1.5707963267948966" xyz=" 0.00 -0.11950 0.0"/>
  </joint>
  <!-- leg_Xa: shoulder  -->
  <link name="leg_4a">
    <visual>
      <origin rpy="0 0 0" xyz="0 0 0"/>
      <geometry>
        <mesh filename="file:///home/laroto/antsy/install/antsy_description/share/antsy_description/meshes/simple_meshes/coxa_simple.stl" scale="0.001 0.001 0.001"/>
      </geometry>
      <material name="feet"/>
    </visual>
    <collision>
      <origin xyz="0.021875 0.05 0.05"/>
      <geometry>
        <box size="0.04375 0.05 0.05"/>
      </geometry>
    </collision>
    <inertial>
      <mass value="0.09"/>
      <!-- changed from 0.06644962989519385 -->
      <origin xyz="0.021875 0 0"/>
      <inertia ixx="3.4e-05" ixy="-0.0" ixz="-0.0" iyy="3.2e-05" iyz="0.0" izz="2.4e-05"/>
    </inertial>
  </link>
  <joint name="leg_4_base__leg_4a" type="revolute">
    <axis xyz="0 0 1"/>
    <limit effort="4.25" lower="-1.5708" upper="1.5708" velocity="110.2"/>
    <parent link="leg_4"/>
    <child link="leg_4a"/>
    <dynamics damping="0.1" friction="0.3"/>
  </joint>
  <!-- leg_Xb: upper segment -->
  <link name="leg_4b">
    <visual>
      <origin xyz="0 0 0"/>
      <geometry>
        <mesh filename="file:///home/laroto/antsy/install/antsy_description/share/antsy_description/meshes/simple_meshes/tibia_simple.stl" scale="0.001 0.001 0.001"/>
      </geometry>
      <material name="feet"/>
    </visual>
    <collision>
      <origin xyz="0.05 0 0"/>
      <geometry>
        <box size="0.1 0.06 0.025"/>
      </geometry>
    </collision>
    <inertial>
      <mass value="0.08"/>
      <!-- changed from 0.029822153915739318 -->
      <origin xyz="0.05 0 0"/>
      <inertia ixx="2.7e-05" ixy="0.0" ixz="-0.0" iyy="1.9e-05" iyz="-1e-06" izz="4.1e-05"/>
    </inertial>
  </link>
  <joint name="leg_4a__leg_4b" type="revolute">
    <axis xyz="0 1 0"/>
    <limit effort="4.25" lower="-1.309" upper="2.00713" velocity="110.2"/>
    <parent link="leg_4a"/>
    <child link="leg_4b"/>
    <origin xyz="0.04375 0 -0.010"/>
    <dynamics damping="0.1" friction="0.3"/>
  </joint>
  <!-- leg_Xc: lower segment -->
  <link name="leg_4c">
    <visual>
      <origin rpy="0 -0.35 0" xyz="0 0 0"/>
      <geometry>
        <mesh filename="file:///home/laroto/antsy/install/antsy_description/share/antsy_description/meshes/simple_meshes/foot_simple.stl" scale="0.001 0.001 0.001"/>
      </geometry>
      <material name="feet"/>
    </visual>
    <visual>
      <origin xyz="0.15 0 0"/>
      <geometry>
        <sphere radius="0.0075"/>
      </geometry>
      <material name="feet"/>
    </visual>
    <collision>
      <origin xyz="0.075 0 0"/>
      <geometry>
        <box size="0.15 0.045 0.05"/>
      </geometry>
    </collision>
    <collision>
      <origin xyz="0.15 0 0"/>
      <geometry>
        <sphere radius="0.0075"/>
      </geometry>
      <contact_coefficients mu="0.7"/>
    </collision>
    <inertial>
      <mass value="0.030"/>
      <!-- changed from 0.08076187945098641 -->
      <origin rpy="0 -0.35 0" xyz="0.075 0 0"/>
      <inertia ixx="0.000205" ixy="2e-06" ixz="-0.0" iyy="3.9e-05" iyz="4.1e-05" izz="0.000199"/>
    </inertial>
  </link>
  <joint name="leg_4b__leg_4c" type="revolute">
    <axis xyz="0 -1 0"/>
    <limit effort="4.25" lower="-2.0944" upper="2.35619" velocity="110.2"/>
    <parent link="leg_4b"/>
    <child link="leg_4c"/>
    <origin rpy="0 0.35 0" xyz="0.1 0 0"/>
    <dynamics damping="0.1" friction="0.3"/>
  </joint>
  <!-- Link in the foot ball center to easily refer to that point in KDL -->
  <link name="foot_4"/>
  <joint name="leg_4c__foot_4" type="fixed">
    <parent link="leg_4c"/>
    <child link="foot_4"/>
    <origin rpy="0 0.4 0" xyz="0.15 0 0"/>
  </joint>
  <gazebo>
    <plugin filename="gz-sim-joint-position-controller-system" name="gz::sim::systems::JointPositionController">
      <joint_name>leg_4_base__leg_4a</joint_name>
      <use_actuator_msg>true</use_actuator_msg>
      <actuator_number>12</actuator_number>
      <cmd_max>4.25</cmd_max>
      <cmd_min>-4.25</cmd_min>
      <p_gain>17.8</p_gain>
      <i_gain>0.</i_gain>
      <d_gain>0.</d_gain>
    </plugin>
  </gazebo>
  <gazebo>
    <plugin filename="gz-sim-joint-position-controller-system" name="gz::sim::systems::JointPositionController">
      <joint_name>leg_4a__leg_4b</joint_name>
      <use_actuator_msg>true</use_actuator_msg>
      <actuator_number>13</actuator_number>
      <cmd_max>4.25</cmd_max>
      <cmd_min>-4.25</cmd_min>
      <p_gain>17.8</p_gain>
      <i_gain>0.</i_gain>
      <d_gain>0.</d_gain>
    </plugin>
  </gazebo>
  <gazebo>
    <plugin filename="gz-sim-joint-position-controller-system" name="gz::sim::systems::JointPositionController">
      <joint_name>leg_4b__leg_4c</joint_name>
      <use_actuator_msg>true</use_actuator_msg>
      <actuator_number>14</actuator_number>
      <cmd_max>4.25</cmd_max>
      <cmd_min>-4.25</cmd_min>
      <p_gain>17.8</p_gain>
      <i_gain>0.</i_gain>
      <d_gain>0.</d_gain>
    </plugin>
  </gazebo>
  <!-- leg_X: fixed to base_link -->
  <link name="leg_5"/>
  <joint name="base_link__leg_5" type="fixed">
    <parent link="base_link"/>
    <child link="leg_5"/>
    <origin rpy="0 0 -0.5235963267948966" xyz=" 0.138 -0.0875 0.0"/>
  </joint>
  <!-- leg_Xa: shoulder  -->
  <link name="leg_5a">
    <visual>
      <origin rpy="0 0 0" xyz="0 0 0"/>
      <geometry>
        <mesh filename="file:///home/laroto/antsy/install/antsy_description/share/antsy_description/meshes/simple_meshes/coxa_simple.stl" scale="0.001 0.001 0.001"/>
      </geometry>
      <material name="feet"/>
    </visual>
    <collision>
      <origin xyz="0.021875 0.05 0.05"/>
      <geometry>
        <box size="0.04375 0.05 0.05"/>
      </geometry>
    </collision>
    <inertial>
      <mass value="0.09"/>
      <!-- changed from 0.06644962989519385 -->
      <origin xyz="0.021875 0 0"/>
      <inertia ixx="3.4e-05" ixy="-0.0" ixz="-0.0" iyy="3.2e-05" iyz="0.0" izz="2.4e-05"/>
    </inertial>
  </link>
  <joint name="leg_5_base__leg_5a" type="revolute">
    <axis xyz="0 0 1"/>
    <limit effort="4.25" lower="-1.5708" upper="1.5708" velocity="110.2"/>
    <parent link="leg_5"/>
    <child link="leg_5a"/>
    <dynamics damping="0.1" friction="0.3"/>
  </joint>
  <!-- leg_Xb: upper segment -->
  <link name="leg_5b">
    <visual>
      <origin xyz="0 0 0"/>
      <geometry>
        <mesh filename="file:///home/laroto/antsy/install/antsy_description/share/antsy_description/meshes/simple_meshes/tibia_simple.stl" scale="0.001 0.001 0.001"/>
      </geometry>
      <material name="feet"/>
    </visual>
    <collision>
      <origin xyz="0.05 0 0"/>
      <geometry>
        <box size="0.1 0.06 0.025"/>
      </geometry>
    </collision>
    <inertial>
      <mass value="0.08"/>
      <!-- changed from 0.029822153915739318 -->
      <origin xyz="0.05 0 0"/>
      <inertia ixx="2.7e-05" ixy="0.0" ixz="-0.0" iyy="1.9e-05" iyz="-1e-06" izz="4.1e-05"/>
    </inertial>
  </link>
  <joint name="leg_5a__leg_5b" type="revolute">
    <axis xyz="0 1 0"/>
    <limit effort="4.25" lower="-1.309" upper="2.00713" velocity="110.2"/>
    <parent link="leg_5a"/>
    <child link="leg_5b"/>
    <origin xyz="0.04375 0 -0.010"/>
    <dynamics damping="0.1" friction="0.3"/>
  </joint>
  <!-- leg_Xc: lower segment -->
  <link name="leg_5c">
    <visual>
      <origin rpy="0 -0.35 0" xyz="0 0 0"/>
      <geometry>
        <mesh filename="file:///home/laroto/antsy/install/antsy_description/share/antsy_description/meshes/simple_meshes/foot_simple.stl" scale="0.001 0.001 0.001"/>
      </geometry>
      <material name="feet"/>
    </visual>
    <visual>
      <origin xyz="0.15 0 0"/>
      <geometry>
        <sphere radius="0.0075"/>
      </geometry>
      <material name="feet"/>
    </visual>
    <collision>
      <origin xyz="0.075 0 0"/>
      <geometry>
        <box size="0.15 0.045 0.05"/>
      </geometry>
    </collision>
    <collision>
      <origin xyz="0.15 0 0"/>
      <geometry>
        <sphere radius="0.0075"/>
      </geometry>
      <contact_coefficients mu="0.7"/>
    </collision>
    <inertial>
      <mass value="0.030"/>
      <!-- changed from 0.08076187945098641 -->
      <origin rpy="0 -0.35 0" xyz="0.075 0 0"/>
      <inertia ixx="0.000205" ixy="2e-06" ixz="-0.0" iyy="3.9e-05" iyz="4.1e-05" izz="0.000199"/>
    </inertial>
  </link>
  <joint name="leg_5b__leg_5c" type="revolute">
    <axis xyz="0 -1 0"/>
    <limit effort="4.25" lower="-2.0944" upper="2.35619" velocity="110.2"/>
    <parent link="leg_5b"/>
    <child link="leg_5c"/>
    <origin rpy="0 0.35 0" xyz="0.1 0 0"/>
    <dynamics damping="0.1" friction="0.3"/>
  </joint>
  <!-- Link in the foot ball center to easily refer to that point in KDL -->
  <link name="foot_5"/>
  <joint name="leg_5c__foot_5" type="fixed">
    <parent link="leg_5c"/>
    <child link="foot_5"/>
    <origin rpy="0 0.4 0" xyz="0.15 0 0"/>
  </joint>
  <gazebo>
    <plugin filename="gz-sim-joint-position-controller-system" name="gz::sim::systems::JointPositionController">
      <joint_name>leg_5_base__leg_5a</joint_name>
      <use_actuator_msg>true</use_actuator_msg>
      <actuator_number>15</actuator_number>
      <cmd_max>4.25</cmd_max>
      <cmd_min>-4.25</cmd_min>
      <p_gain>17.8</p_gain>
      <i_gain>0.</i_gain>
      <d_gain>0.</d_gain>
    </plugin>
  </gazebo>
  <gazebo>
    <plugin filename="gz-sim-joint-position-controller-system" name="gz::sim::systems::JointPositionController">
      <joint_name>leg_5a__leg_5b</joint_name>
      <use_actuator_msg>true</use_actuator_msg>
      <actuator_number>16</actuator_number>
      <cmd_max>4.25</cmd_max>
      <cmd_min>-4.25</cmd_min>
      <p_gain>17.8</p_gain>
      <i_gain>0.</i_gain>
      <d_gain>0.</d_gain>
    </plugin>
  </gazebo>
  <gazebo>
    <plugin filename="gz-sim-joint-position-controller-system" name="gz::sim::systems::JointPositionController">
      <joint_name>leg_5b__leg_5c</joint_name>
      <use_actuator_msg>true</use_actuator_msg>
      <actuator_number>17</actuator_number>
      <cmd_max>4.25</cmd_max>
      <cmd_min>-4.25</cmd_min>
      <p_gain>17.8</p_gain>
      <i_gain>0.</i_gain>
      <d_gain>0.</d_gain>
    </plugin>
  </gazebo>
  <!-- Sensors -->
  <link name="imu"/>
  <joint name="base_link__imu" type="fixed">
    <parent link="base_link"/>
    <child link="imu"/>
    <!-- TODO set correct pose -->
    <origin xyz="0 0 0.05"/>
  </joint>
  <!-- Gazebo (simulation only) -->
  <!-- docs: https://github.com/gazebosim/gz-sim/tree/main/src/systems -->
  <gazebo>
    <plugin filename="gz-sim-odometry-publisher-system" name="gz::sim::systems::OdometryPublisher">
      <odom_publish_frequency>50</odom_publish_frequency>
      <odom_topic>/antsy/odometry</odom_topic>
      <odom_frame>world</odom_frame>
      <robot_base_frame>base_link</robot_base_frame>
    </plugin>
    <plugin filename="gz-sim-joint-state-publisher-system" name="gz::sim::systems::JointStatePublisher">
      <topic>/antsy/joint_state</topic>
    </plugin>
    <!-- TODO doesn't work, no imu topic in Gazebo gets published -->
    <plugin filename="gz-sim-imu-system" name="gz::sim::systems::Imu">
      <topic>/antsy/imu</topic>
    </plugin>
  </gazebo>
</robot>
